[2024-06-07T18:09:59.181+0000] {local_task_job_runner.py:120} INFO - ::group::Pre task execution logs
[2024-06-07T18:09:59.191+0000] {taskinstance.py:2076} INFO - Dependencies all met for dep_context=non-requeueable deps ti=<TaskInstance: car_price_prediction.predict manual__2024-06-07T18:09:38.734705+00:00 [queued]>
[2024-06-07T18:09:59.194+0000] {taskinstance.py:2076} INFO - Dependencies all met for dep_context=requeueable deps ti=<TaskInstance: car_price_prediction.predict manual__2024-06-07T18:09:38.734705+00:00 [queued]>
[2024-06-07T18:09:59.194+0000] {taskinstance.py:2306} INFO - Starting attempt 1 of 2
[2024-06-07T18:09:59.201+0000] {taskinstance.py:2330} INFO - Executing <Task(PythonOperator): predict> on 2024-06-07 18:09:38.734705+00:00
[2024-06-07T18:09:59.209+0000] {warnings.py:110} WARNING - /home/***/.local/lib/python3.12/site-packages/***/task/task_runner/standard_task_runner.py:61: DeprecationWarning: This process (pid=431) is multi-threaded, use of fork() may lead to deadlocks in the child.
  pid = os.fork()

[2024-06-07T18:09:59.210+0000] {standard_task_runner.py:63} INFO - Started process 445 to run task
[2024-06-07T18:09:59.210+0000] {standard_task_runner.py:90} INFO - Running: ['***', 'tasks', 'run', 'car_price_prediction', 'predict', 'manual__2024-06-07T18:09:38.734705+00:00', '--job-id', '2880', '--raw', '--subdir', 'DAGS_FOLDER/hw_dag.py', '--cfg-path', '/tmp/tmplfnfkcz5']
[2024-06-07T18:09:59.211+0000] {standard_task_runner.py:91} INFO - Job 2880: Subtask predict
[2024-06-07T18:09:59.234+0000] {task_command.py:426} INFO - Running <TaskInstance: car_price_prediction.predict manual__2024-06-07T18:09:38.734705+00:00 [running]> on host 23149627dc8e
[2024-06-07T18:09:59.279+0000] {taskinstance.py:2648} INFO - Exporting env vars: AIRFLOW_CTX_DAG_OWNER='***' AIRFLOW_CTX_DAG_ID='car_price_prediction' AIRFLOW_CTX_TASK_ID='predict' AIRFLOW_CTX_EXECUTION_DATE='2024-06-07T18:09:38.734705+00:00' AIRFLOW_CTX_TRY_NUMBER='1' AIRFLOW_CTX_DAG_RUN_ID='manual__2024-06-07T18:09:38.734705+00:00'
[2024-06-07T18:09:59.280+0000] {taskinstance.py:430} INFO - ::endgroup::
[2024-06-07T18:09:59.280+0000] {taskinstance.py:441} INFO - ::group::Post task execution logs
[2024-06-07T18:09:59.280+0000] {taskinstance.py:2905} ERROR - Task failed with exception
Traceback (most recent call last):
  File "/home/airflow/.local/lib/python3.12/site-packages/airflow/models/taskinstance.py", line 465, in _execute_task
    result = _execute_callable(context=context, **execute_callable_kwargs)
             ^^^^^^^^^^^^^^^^^^^^^^^^^^^^^^^^^^^^^^^^^^^^^^^^^^^^^^^^^^^^^
  File "/home/airflow/.local/lib/python3.12/site-packages/airflow/models/taskinstance.py", line 432, in _execute_callable
    return execute_callable(context=context, **execute_callable_kwargs)
           ^^^^^^^^^^^^^^^^^^^^^^^^^^^^^^^^^^^^^^^^^^^^^^^^^^^^^^^^^^^^
  File "/home/airflow/.local/lib/python3.12/site-packages/airflow/models/baseoperator.py", line 400, in wrapper
    return func(self, *args, **kwargs)
           ^^^^^^^^^^^^^^^^^^^^^^^^^^^
  File "/home/airflow/.local/lib/python3.12/site-packages/airflow/operators/python.py", line 235, in execute
    return_value = self.execute_callable()
                   ^^^^^^^^^^^^^^^^^^^^^^^
  File "/home/airflow/.local/lib/python3.12/site-packages/airflow/operators/python.py", line 252, in execute_callable
    return self.python_callable(*self.op_args, **self.op_kwargs)
           ^^^^^^^^^^^^^^^^^^^^^^^^^^^^^^^^^^^^^^^^^^^^^^^^^^^^^
  File "/home/airflow/airflow_hw/modules/predict.py", line 27, in predict
    model_filename = os.listdir(f'{path}/data/models/')[-1]
                     ^^^^^^^^^^^^^^^^^^^^^^^^^^^^^^^^^^
FileNotFoundError: [Errno 2] No such file or directory: './data/models/'
[2024-06-07T18:09:59.285+0000] {taskinstance.py:1206} INFO - Marking task as UP_FOR_RETRY. dag_id=car_price_prediction, task_id=predict, run_id=manual__2024-06-07T18:09:38.734705+00:00, execution_date=20240607T180938, start_date=20240607T180959, end_date=20240607T180959
[2024-06-07T18:09:59.291+0000] {standard_task_runner.py:110} ERROR - Failed to execute job 2880 for task predict ([Errno 2] No such file or directory: './data/models/'; 445)
[2024-06-07T18:09:59.302+0000] {local_task_job_runner.py:240} INFO - Task exited with return code 1
[2024-06-07T18:09:59.311+0000] {taskinstance.py:3498} INFO - 0 downstream tasks scheduled from follow-on schedule check
[2024-06-07T18:09:59.313+0000] {local_task_job_runner.py:222} INFO - ::endgroup::
